Workbook

Sheet Run Notes
B2: RUN NOTES
B4: Source file
B5: Periods
B6: Status
B7: Accounts mapped
B8: Calculation policy
B9: Notes

Sheet COA
B2: COA_ID | W2: MAPPED LABELS | X2: MODEL FEEDBACK | Y2: VENUE NAME
B3: S12.rooms_available
B4: S12.rooms_sold
B5: S12.occupancy
B6: S12.adr
B7: S12.revpar
B8: S12.total_rooms_revenue
B9: S12.total_food_and_beverage_revenue
B10: S12.total_other_operated_departments_revenue
B11: S12.total_miscellaneous_income
B12: S12.total_revenue
B13: S12.total_rooms_expenses
B14: S12.total_food_and_beverage_expenses
... B273: S11.total_non_operating_income_and_expenses

Sheet KHP Model Accounts
B14: KHP UNDERWRITING MODEL INPUTS
C17: =COA!C2 -> 0
B19: Keys | C19: =C20/365 -> 0
B20: Rooms Available | C20: =COA!C3 -> 0
B21: Rooms Sold | C21: =COA!C4 -> 0
B29: Occupancy | C29: =COA!C5 -> 0
B30: ADR | C30: =COA!C6 -> 0
B31: RevPAR | C31: =C29*C30 -> 0
B32: Total RevPAR | C32: =C61/C20 -> #DIV/0!
B33: GOPAR | C33: =C217/C20 -> #DIV/0!
B35: Revenue (POR)
B36: Rooms | C36: =COA!C8 -> 0
B37: Food & Beverage | C37: =SUM(C38:C46) -> 0
B38: Mini Bar | C38: 0
B39: Room Service | C39: =SUM(COA!C97,COA!C112) -> 0
B40: =COA!Y86 -> 0 | C40: =SUM(COA!C86,COA!C101) -> 0
B41: =COA!Y87 -> 0 | C41: =SUM(COA!C87,COA!C102) -> 0
B42: =COA!Y88 -> 0 | C42: =SUM(COA!C88,COA!C103) -> 0
B43: =COA!Y89 -> 0 | C43: =SUM(COA!C89,COA!C104) -> 0
B44: All other F&B Revenue / F&B Allowances | C44: =SUM(COA!C90:C93,COA!C105:C108,COA!C98,COA!C113) -> 0
B45: Banquets | C45: =SUM(COA!C96,COA!C111) -> 0
B46: Other F&B Revenue | C46: =COA!C9-SUM('KHP Model Accounts'!C38:C45) -> 0
B47: Parking | C47: =COA!C146 -> 0
B48: Spa | C48: =SUM(C49:C50) -> 0
B49: Spa Services | C49: =COA!C153-'KHP Model Accounts'!C50 -> 0
B50: Spa Shop | C50: =COA!C151 -> 0
B51: Retail Shop | C51: =COA!C158 -> 0
B52: Other Operated | C52: =SUM(C53:C55) -> 0
B53: Recreation | C53: =COA!C163 -> 0
B54: Golf | C54: =COA!C167 -> 0
B55: All Other OOD | C55: =COA!C10-SUM('KHP Model Accounts'!C53:C54,'KHP Model Accounts'!C47:C48,C51) -> 0
B56: Miscellaneous Income | C56: =SUM(C57:C59) -> 0
B57: Resort Fees | C57: =COA!C174 -> 0
B58: Space Rental | C58: =COA!C175 -> 0
B59: Other Misc. Income | C59: =COA!C11-SUM('KHP Model Accounts'!C57:C58) -> 0
B61: Total Revenue | C61: =SUM(C56,C51:C52,C47:C48,C36:C37) -> 0
B62: Total Revenue (POR) | C62: =C61/C21 -> #DIV/0!
B64: Departmental Expenses
B65: Rooms
B66: Salaries & Wages (POR) | C66: =SUM(COA!C63,COA!C65) -> 0
...
